Workbook

Sheet Premissas
A1: Premissa | B1: Valor
A2: Crescimento mensal receita (%)
A3: Ticket médio MUVX
A4: Qtd trainers ativos
A5: Alunos por trainer
A6: % Comissão média
A7: Custos fixos mensais
A8: Despesas variáveis (% receita)
A13: Incluir projeções de vendas

Sheet DRE_Mensal
B1: TRAÇÃO | F1: ESCALA
A2: Categoria | B2: Jan/26 | C2: Feb/26 | D2: Mar/26 | E2: Apr/26 | F2: May/26 | G2: Jun/26 | H2: Jul/26 | I2: Aug/26 | J2: Sep/26 | K2: Oct/26 | L2: Nov/26 | M2: Dec/26
A3: Receita Operacional | B3: =Fluxo_Caixa_Mensal!H4 -> 0 | C3: =Fluxo_Caixa_Mensal!I4 -> 0 | D3: =Fluxo_Caixa_Mensal!J4 -> 0 | E3: =Fluxo_Caixa_Mensal!K4 -> 83839.594 | F3: =Fluxo_Caixa_Mensal!L4 -> 157390.49 | G3: =Fluxo_Caixa_Mensal!M4 -> 311990.17 | H3: =Fluxo_Caixa_Mensal!N4 -> 752576.37 | I3: =Fluxo_Caixa_Mensal!O4 -> 1662897.6 | ... M3: =Fluxo_Caixa_Mensal!S4 -> 7049208.6
A4: COGS | B4: =Fluxo_Caixa_Mensal!H76 -> 0 | C4: =Fluxo_Caixa_Mensal!I76 -> 0 | D4: =Fluxo_Caixa_Mensal!J76 -> 3300 | E4: =Fluxo_Caixa_Mensal!K76 -> 3300 | F4: =Fluxo_Caixa_Mensal!L76 -> 7826.4 | G4: =Fluxo_Caixa_Mensal!M76 -> 15052.8 | H4: =Fluxo_Caixa_Mensal!N76 -> 23042.4 | I4: =Fluxo_Caixa_Mensal!O76 -> 31272 | ... M4: =Fluxo_Caixa_Mensal!S76 -> 57874.963
A5: Resultado Bruto | B5: =B3-B4 -> 0 | C5: =C3-C4 -> 0 | D5: =D3-D4 -> -3300 | E5: =E3-E4 -> 80539.594 | F5: =F3-F4 -> 149564.09 | G5: =G3-G4 -> 296937.37 | H5: =H3-H4 -> 729533.97 | I5: =I3-I4 -> 1631625.6 | ... M5: =M3-M4 -> 6991333.7
A6: Custos Fixos | B6: =Fluxo_Caixa_Mensal!H26 -> 145929.15 | C6: =Fluxo_Caixa_Mensal!I26 -> 173607.66 | D6: =Fluxo_Caixa_Mensal!J26 -> 156816.4 | E6: =Fluxo_Caixa_Mensal!K26 -> 146809.87 | F6: =Fluxo_Caixa_Mensal!L26 -> 106584.09 | G6: =Fluxo_Caixa_Mensal!M26 -> 122702.5 | H6: =Fluxo_Caixa_Mensal!N26 -> 188251.75 | I6: =Fluxo_Caixa_Mensal!O26 -> 271393.51 | ... M6: =Fluxo_Caixa_Mensal!S26 -> 484218.94
A7: Despesas Variáveis | B7: =Fluxo_Caixa_Mensal!H86 -> 76755.16 | C7: =Fluxo_Caixa_Mensal!I86 -> 41903.51 | D7: =Fluxo_Caixa_Mensal!J86 -> 51966.51 | E7: =Fluxo_Caixa_Mensal!K86 -> 56252.17 | F7: =Fluxo_Caixa_Mensal!L86 -> 84221.646 | G7: =Fluxo_Caixa_Mensal!M86 -> 123155.67 | H7: =Fluxo_Caixa_Mensal!N86 -> 371408.01 | I7: =Fluxo_Caixa_Mensal!O86 -> 463246.73 | ... M7: =Fluxo_Caixa_Mensal!S86 -> 904607.97
A8: Resultado Operacional | B8: =B5-B6-B7 -> -222684.31 | C8: =C5-C6-C7 -> -215511.17 | D8: =D5-D6-D7 -> -212082.91 | E8: =E5-E6-E7 -> -122522.45 | F8: =F5-F6-F7 -> -41241.65 | G8: =G5-G6-G7 -> 51079.2 | H8: =H5-H6-H7 -> 169874.21 | I8: =I5-I6-I7 -> 896985.32 | ... M8: =M5-M6-M7 -> 5602506.8
A9: Depreciação | B9: 0 | C9: 0 | D9: 0 | E9: 0 | F9: 0 | G9: 0 | H9: 0 | I9: 0 | J9: 0 | K9: 0 | L9: 0 | M9: 0
A10: Amortização | B10: 0 | C10: 0 | D10: 0 | E10: 0 | F10: 0 | G10: 0 | H10: 0 | I10: 0 | J10: 0 | K10: 0 | L10: 0 | M10: 0
A11: EBITDA | B11: =B8-B9-B10 -> -222684.31 | C11: =C8-C9-C10 -> -215511.17 | D11: =D8-D9-D10 -> -212082.91 | E11: =E8-E9-E10 -> -122522.45 | F11: =F8-F9-F10 -> -41241.65 | G11: =G8-G9-G10 -> 51079.2 | H11: =H8-H9-H10 -> 169874.21 | I11: =I8-I9-I10 -> 896985.32 | ... M11: =M8-M9-M10 -> 5602506.8
A12: Margem Bruta | B12: =IFERROR(B5/B3,0) -> 0 | C12: =IFERROR(C5/C3,0) -> 0 | D12: =IFERROR(D5/D3,0) -> 0 | E12: =IFERROR(E5/E3,0) -> 0.96063912 | F12: =IFERROR(F5/F3,0) -> 0.950274 | G12: =IFERROR(G5/G3,0) -> 0.95175233 | H12: =IFERROR(H5/H3,0) -> 0.96938198 | I12: =IFERROR(I5/I3,0) -> 0.98119427 | ... M12: =IFERROR(M5/M3,0) -> 0.99178986
A13: Margem Operacional | B13: =IFERROR(B8/B3,0) -> 0 | C13: =IFERROR(C8/C3,0) -> 0 | D13: =IFERROR(D8/D3,0) -> 0 | E13: =IFERROR(E8/E3,0) -> -1.4613912 | F13: =IFERROR(F8/F3,0) -> -0.26203395 | G13: =IFERROR(G8/G3,0) -> 0.16372054 | H13: =IFERROR(H8/H3,0) -> 0.22572355 | I13: =IFERROR(I8/I3,0) -> 0.53941105 | ... M13: =IFERROR(M8/M3,0) -> 0.79477102
A14: Margem EBITDA | B14: =IFERROR(B11/B3,0) -> 0 | C14: =IFERROR(C11/C3,0) -> 0 | D14: =IFERROR(D11/D3,0) -> 0 | E14: =IFERROR(E11/E3,0) -> -1.4613912 | F14: =IFERROR(F11/F3,0) -> -0.26203395 | G14: =IFERROR(G11/G3,0) -> 0.16372054 | H14: =IFERROR(H11/H3,0) -> 0.22572355 | I14: =IFERROR(I11/I3,0) -> 0.53941105 | ... M14: =IFERROR(M11/M3,0) -> 0.79477102
A15: Burn Rate (Operacional) | B15: =Fluxo_Caixa_Mensal!H25-Fluxo_Caixa_Mensal!H4 -> 222684.31 | C15: =Fluxo_Caixa_Mensal!I25-Fluxo_Caixa_Mensal!I4 -> 215511.17 | D15: =Fluxo_Caixa_Mensal!J25-Fluxo_Caixa_Mensal!J4 -> 212082.91 | E15: =Fluxo_Caixa_Mensal!K25-Fluxo_Caixa_Mensal!K4 -> 122522.45 | F15: =Fluxo_Caixa_Mensal!L25-Fluxo_Caixa_Mensal!L4 -> 46272.026 | G15: =Fluxo_Caixa_Mensal!M25-Fluxo_Caixa_Mensal!M4 -> -41635.771 | H15: =Fluxo_Caixa_Mensal!N25-Fluxo_Caixa_Mensal!N4 -> -151154.8 | I15: =Fluxo_Caixa_Mensal!O25-Fluxo_Caixa_Mensal!O4 -> -851830.74 | ... M15: =Fluxo_Caixa_Mensal!S25-Fluxo_Caixa_Mensal!S4 -> -5266556.2
A16: Runway (Médio) | B16: =Fluxo_Caixa_Mensal!H167/(AVERAGE(DRE_Mensal!$B$15:$F$15)) -> 0.015190651 | C16: =Fluxo_Caixa_Mensal!I167/(AVERAGE(DRE_Mensal!$B$15:$F$15)) -> -0.030135475 | D16: =Fluxo_Caixa_Mensal!J167/(AVERAGE(DRE_Mensal!$B$15:$F$15)) -> 0.018854794 | E16: =Fluxo_Caixa_Mensal!K167/(AVERAGE(DRE_Mensal!$B$15:$F$15)) -> -0.20714736 | F16: =Fluxo_Caixa_Mensal!L167/(AVERAGE(DRE_Mensal!$B$15:$F$15)) -> -0.30835964 | G16: N/A | H16: N/A | I16: N/A | J16: N/A | K16: N/A | L16: N/A | M16: N/A
A17: Runway (Mensal) | B17: =Fluxo_Caixa_Mensal!H167/DRE_Mensal!B15 -> 0.011174788 | C17: =Fluxo_Caixa_Mensal!I167/DRE_Mensal!C15 -> -0.022906609 | D17: =Fluxo_Caixa_Mensal!J167/DRE_Mensal!D15 -> 0.014563597 | E17: =Fluxo_Caixa_Mensal!K167/DRE_Mensal!E15 -> -0.2769595 | F17: =Fluxo_Caixa_Mensal!L167/DRE_Mensal!F15 -> -1.0916704 | G17: N/A | H17: N/A | I17: N/A | J17: N/A | K17: N/A | L17: N/A | M17: N/A
A18: Tx Crescimento | E18: =E11/F11 -> 2.9708425 | F18: =F11/G11 -> -0.80740595 | G18: =G11/H11 -> 0.30068838 | H18: =H11/I11 -> 0.18938349 | I18: =I11/J11 -> 0.46450903 | J18: =J11/K11 -> 0.64610633 | K18: =K11/L11 -> 0.6861819 | L18: =L11/M11 -> 0.77743758

Sheet Fluxo_Caixa_Mensal
B1: PROJETO | F1: GO-LIVE E HYPERCARE | H1: TRAÇÃO | L1: PRÉ-ESCALA
A2: Categoria | B2: 45839 | C2: 45870 | D2: 45901 | E2: 45931 | F2: 45962 | G2: 45992 | H2: 46023 | I2: 46054 | J2: 46082 | K2: 46113 | L2: 46143 | M2: 46174 | N2: 46204 | O2: 46235 | P2: 46266 | Q2: 46296 | R2: 46327 | S2: 46357 | T2: Total Anual (2026)
A3: Valuation Estimado (ARR-Based) | B3: =C5*4 -> 0 | C3: =D5*4 -> 0 | D3: =E5*4 -> 0 | E3: =F5*4 -> 0 | F3: =G5*4 -> 0 | G3: =H5*4 -> 0 | H3: =(I5*12)*4 -> 0 | I3: =(J5*12)*4 -> 0 | J3: =(K5*12)*4 -> 4024300.5 | K3: =(L5*12)*4 -> 7554743.3 | L3: =(M5*12)*4 -> 14975528 | M3: =(N5*12)*4 -> 36123666 | N3: =(O5*12)*4 -> 79819083 | O3: =(P5*12)*4 -> 1.3526606e+08 | ... R3: =(S5*12)*4 -> 3.3836201e+08
A4: Entradas Operacionais | B4: =B5+B20 -> 0 | C4: =C5+C20 -> 0 | D4: =D5+D20 -> 0 | E4: =E5+E20 -> 0 | F4: =F5+F20 -> 0 | G4: =G5+G20 -> 0 | H4: =H5+H20 -> 0 | I4: =I5+I20 -> 0 | ... S4: =S5+S20 -> 7049208.6 | T4: =SUM(H4:S4) -> 22497351
A5: Receita Recorrente / Transacional | B5: =SUM(B6:B19) -> 0 | C5: =SUM(C6:C19) -> 0 | D5: =SUM(D6:D19) -> 0 | E5: =SUM(E6:E19) -> 0 | F5: =SUM(F6:F19) -> 0 | G5: =SUM(G6:G19) -> 0 | H5: =SUM(H6:H19) -> 0 | I5: =SUM(I6:I19) -> 0 | ... S5: =SUM(S6:S19) -> 7049208.6 | T5: =SUM(H5:S5) -> 22497351
A6: Receita MUVX % - Estimado | B6: 0 | C6: 0 | D6: 0 | E6: 0 | F6: 0 | G6: 0 | H6: 0 | I6: 0 | K6: {=INDEX('Proj. Vendas MUVX Core New'!$AD$66:$AD$76, COLUMN(K6)-COLUMN($J$6)+1)} -> 14932.917 | L6: {=INDEX('Proj. Vendas MUVX Core New'!$AD$66:$AD$76, COLUMN(L6)-COLUMN($J$6)+1)} -> 16062.562 | M6: {=INDEX('Proj. Vendas MUVX Core New'!$AD$66:$AD$76, COLUMN(M6)-COLUMN($J$6)+1)} -> 21040.331 | N6: {=INDEX('Proj. Vendas MUVX Core New'!$AD$66:$AD$76, COLUMN(N6)-COLUMN($J$6)+1)} -> 64678.342 | O6: {=INDEX('Proj. Vendas MUVX Core New'!$AD$66:$AD$76, COLUMN(O6)-COLUMN($J$6)+1)} -> 215065.82 | P6: {=INDEX('Proj. Vendas MUVX Core New'!$AD$66:$AD$76, COLUMN(P6)-COLUMN($J$6)+1)} -> 368901.16 | Q6: {=INDEX('Proj. Vendas MUVX Core New'!$AD$66:$AD$76, COLUMN(Q6)-COLUMN($J$6)+1)} -> 528847.3 | R6: {=INDEX('Proj. Vendas MUVX Core New'!$AD$66:$AD$76, COLUMN(R6)-COLUMN($J$6)+1)} -> 689647.23 | S6: {=INDEX('Proj. Vendas MUVX Core New'!$AD$66:$AD$76, COLUMN(S6)-COLUMN($J$6)+1)} -> 867828.03 | T6: =SUM(H6:S6) -> 2787003.7
A7: Receita MUVX % - Realizado | B7: 0 | C7: 0 | D7: 0 | E7: 0 | F7: 0 | G7: 0 | H7: 0 | I7: 0 | K7: 0 | L7: 0 | M7: 0 | N7: 0 | O7: 0 | P7: 0 | Q7: 0 | R7: 0 | S7: 0 | T7: =SUM(H7:S7) -> 0
A8: Receita MUVX Premium - Estimado | B8: 0 | C8: 0 | D8: 0 | E8: 0 | F8: 0 | G8: 0 | H8: 0 | I8: 0 | K8: {=INDEX('Proj. Vendas MUVX Core New'!$AE$66:$AE$77, COLUMN(K8)-COLUMN($J$8)+1)} -> 9414.1024 | L8: {=INDEX('Proj. Vendas MUVX Core New'!$AE$66:$AE$77, COLUMN(L8)-COLUMN($J$8)+1)} -> 11796.707 | M8: {=INDEX('Proj. Vendas MUVX Core New'!$AE$66:$AE$77, COLUMN(M8)-COLUMN($J$8)+1)} -> 33240.877 | N8: {=INDEX('Proj. Vendas MUVX Core New'!$AE$66:$AE$77, COLUMN(N8)-COLUMN($J$8)+1)} -> 106216.9 | O8: {=INDEX('Proj. Vendas MUVX Core New'!$AE$66:$AE$77, COLUMN(O8)-COLUMN($J$8)+1)} -> 178663.47 | P8: {=INDEX('Proj. Vendas MUVX Core New'!$AE$66:$AE$77, COLUMN(P8)-COLUMN($J$8)+1)} -> 251841.82 | Q8: {=INDEX('Proj. Vendas MUVX Core New'!$AE$66:$AE$77, COLUMN(Q8)-COLUMN($J$8)+1)} -> 323204.77 | R8: {=INDEX('Proj. Vendas MUVX Core New'!$AE$66:$AE$77, COLUMN(R8)-COLUMN($J$8)+1)} -> 400423.52 | S8: {=INDEX('Proj. Vendas MUVX Core New'!$AE$66:$AE$77, COLUMN(S8)-COLUMN($J$8)+1)} -> 471771.47 | T8: =SUM(H8:S8) -> 1786573.6
A9: Receita MUVX Premium - Realizado | B9: 0 | C9: 0 | D9: 0 | E9: 0 | F9: 0 | G9: 0 | H9: 0 | I9: 0 | K9: 0 | L9: 0 | M9: 0 | N9: 0 | O9: 0 | P9: 0 | Q9: 0 | R9: 0 | S9: 0 | T9: =SUM(H9:S9) -> 0
A10: Receita MUVX (Alunos) Fee - Estimado | B10: 0 | C10: 0 | D10: 0 | E10: 0 | F10: 0 | G10: 0 | H10: 0 | I10: 0 | K10: {=INDEX('Proj. Vendas MUVX Core New'!$AF$66:$AF$77, COLUMN(K10)-COLUMN($J$10)+1)} -> 4554.33 | L10: {=INDEX('Proj. Vendas MUVX Core New'!$AF$66:$AF$77, COLUMN(L10)-COLUMN($J$10)+1)} -> 5305.2455 | M10: {=INDEX('Proj. Vendas MUVX Core New'!$AF$66:$AF$77, COLUMN(M10)-COLUMN($J$10)+1)} -> 12031.322 | N10: {=INDEX('Proj. Vendas MUVX Core New'!$AF$66:$AF$77, COLUMN(N10)-COLUMN($J$10)+1)} -> 35063.269 | O10: {=INDEX('Proj. Vendas MUVX Core New'!$AF$66:$AF$77, COLUMN(O10)-COLUMN($J$10)+1)} -> 57895.956 | P10: {=INDEX('Proj. Vendas MUVX Core New'!$AF$66:$AF$77, COLUMN(P10)-COLUMN($J$10)+1)} -> 80959.276 | Q10: {=INDEX('Proj. Vendas MUVX Core New'!$AF$66:$AF$77, COLUMN(Q10)-COLUMN($J$10)+1)} -> 103434.25 | R10: {=INDEX('Proj. Vendas MUVX Core New'!$AF$66:$AF$77, COLUMN(R10)-COLUMN($J$10)+1)} -> 127787.16 | S10: {=INDEX('Proj. Vendas MUVX Core New'!$AF$66:$AF$77, COLUMN(S10)-COLUMN($J$10)+1)} -> 150257.4 | T10: =SUM(H10:S10) -> 577288.2
A11: Receita MUVX (Alunos) Fee - Realizado | B11: 0 | C11: 0 | D11: 0 | E11: 0 | F11: 0 | G11: 0 | H11: 0 | I11: 0 | K11: 0 | L11: 0 | M11: 0 | N11: 0 | O11: 0 | P11: 0 | Q11: 0 | R11: 0 | S11: 0 | T11: =SUM(H11:S11) -> 0
A12: Receita Embaixadores - Estimado | B12: 0 | C12: 0 | D12: 0 | E12: 0 | F12: 0 | G12: 0 | H12: 0 | I12: 0 | K12: 16537.5 | L12: 17364.375 | M12: 18232.594 | N12: 19144.223 | O12: 20101.435 | P12: 21106.506 | Q12: 22161.832 | R12: 23269.923 | S12: 24433.419 | T12: =SUM(H12:S12) -> 182351.81
A13: Receita Embaixadores - Realizado | B13: 0 | C13: 0 | D13: 0 | E13: 0 | F13: 0 | G13: 0 | H13: 0 | I13: 0 | K13: 0 | L13: 0 | M13: 0 | N13: 0 | O13: 0 | P13: 0 | Q13: 0 | R13: 0 | S13: 0 | T13: =SUM(H13:S13) -> 0
A14: Receita Influencer - Estimado | B14: 0 | C14: 0 | D14: 0 | E14: 0 | F14: 0 | G14: 0 | H14: 0 | I14: 0 | K14: {=INDEX('Proj. Vendas Influencia Faixa'!$H$47:$H$58, COLUMN(K14)-COLUMN($J$14)+1)} -> 18105.6 | L14: {=INDEX('Proj. Vendas Influencia Faixa'!$H$47:$H$58, COLUMN(L14)-COLUMN($J$14)+1)} -> 36211.2 | M14: {=INDEX('Proj. Vendas Influencia Faixa'!$H$47:$H$58, COLUMN(M14)-COLUMN($J$14)+1)} -> 63369.6 | N14: {=INDEX('Proj. Vendas Influencia Faixa'!$H$47:$H$58, COLUMN(N14)-COLUMN($J$14)+1)} -> 90528 | O14: {=INDEX('Proj. Vendas Influencia Faixa'!$H$47:$H$58, COLUMN(O14)-COLUMN($J$14)+1)} -> 117686.4 | P14: {=INDEX('Proj. Vendas Influencia Faixa'!$H$47:$H$58, COLUMN(P14)-COLUMN($J$14)+1)} -> 145750.08 | Q14: {=INDEX('Proj. Vendas Influencia Faixa'!$H$47:$H$58, COLUMN(Q14)-COLUMN($J$14)+1)} -> 152793.16 | R14: {=INDEX('Proj. Vendas Influencia Faixa'!$H$47:$H$58, COLUMN(R14)-COLUMN($J$14)+1)} -> 159836.24 | S14: {=INDEX('Proj. Vendas Influencia Faixa'!$H$47:$H$58, COLUMN(S14)-COLUMN($J$14)+1)} -> 166879.32 | T14: =SUM(H14:S14) -> 951159.59
A15: Receita Influencer - Realizado | B15: 0 | C15: 0 | D15: 0 | E15: 0 | F15: 0 | G15: 0 | H15: 0 | I15: 0 | K15: 0 | L15: 0 | M15: 0 | N15: 0 | O15: 0 | P15: 0 | Q15: 0 | R15: 0 | S15: 0 | T15: =SUM(H15:S15) -> 0
A16: Receita MUVX Digital % - Estimado | B16: 0 | C16: 0 | D16: 0 | E16: 0 | F16: 0 | G16: 0 | H16: 0 | I16: 0 | K16: {=INDEX('Proj. Vendas MUVX Digital'!$X$65:$X$73, COLUMN(K16)-COLUMN($K$16)+1)} -> 7161.7101 | L16: {=INDEX('Proj. Vendas MUVX Digital'!$X$65:$X$73, COLUMN(L16)-COLUMN($K$16)+1)} -> 17524.204 | M16: {=INDEX('Proj. Vendas MUVX Digital'!$X$65:$X$73, COLUMN(M16)-COLUMN($K$16)+1)} -> 71950.648 | N16: {=INDEX('Proj. Vendas MUVX Digital'!$X$65:$X$73, COLUMN(N16)-COLUMN($K$16)+1)} -> 126639.33 | O16: {=INDEX('Proj. Vendas MUVX Digital'!$X$65:$X$73, COLUMN(O16)-COLUMN($K$16)+1)} -> 432960.92 | P16: {=INDEX('Proj. Vendas MUVX Digital'!$X$65:$X$73, COLUMN(P16)-COLUMN($K$16)+1)} -> 907108.54 | Q16: {=INDEX('Proj. Vendas MUVX Digital'!$X$65:$X$73, COLUMN(Q16)-COLUMN($K$16)+1)} -> 1498353.9 | R16: {=INDEX('Proj. Vendas MUVX Digital'!$X$65:$X$73, COLUMN(R16)-COLUMN($K$16)+1)} -> 2091384.1 | S16: {=INDEX('Proj. Vendas MUVX Digital'!$X$65:$X$73, COLUMN(S16)-COLUMN($K$16)+1)} -> 3119976.9 | T16: =SUM(H16:S16) -> 8273060.3
A17: Receita MUVX Digital % - Realizado | B17: 0 | C17: 0 | D17: 0 | E17: 0 | F17: 0 | G17: 0 | H17: 0 | I17: 0 | J17: 0 | K17: 0 | L17: 0 | M17: 0 | N17: 0 | O17: 0 | P17: 0 | Q17: 0 | R17: 0 | S17: 0 | T17: =SUM(H17:S17) -> 0
A18: Receita MUVX Digital (Alunos) Fee - Estimado | B18: 0 | C18: 0 | D18: 0 | E18: 0 | F18: 0 | G18: 0 | H18: 0 | I18: 0 | J18: 0 | K18: {=INDEX('Proj. Vendas MUVX Digital'!$Y$65:$Y$73, COLUMN(Y16)-COLUMN($Y$16)+1)} -> 13133.435 | L18: {=INDEX('Proj. Vendas MUVX Digital'!$Y$65:$Y$73, COLUMN(Z16)-COLUMN($Y$16)+1)} -> 53126.193 | M18: {=INDEX('Proj. Vendas MUVX Digital'!$Y$65:$Y$73, COLUMN(AA16)-COLUMN($Y$16)+1)} -> 92124.798 | N18: {=INDEX('Proj. Vendas MUVX Digital'!$Y$65:$Y$73, COLUMN(AB16)-COLUMN($Y$16)+1)} -> 310306.3 | O18: {=INDEX('Proj. Vendas MUVX Digital'!$Y$65:$Y$73, COLUMN(AC16)-COLUMN($Y$16)+1)} -> 640523.57 | P18: {=INDEX('Proj. Vendas MUVX Digital'!$Y$65:$Y$73, COLUMN(AD16)-COLUMN($Y$16)+1)} -> 1042375.6 | Q18: {=INDEX('Proj. Vendas MUVX Digital'!$Y$65:$Y$73, COLUMN(AE16)-COLUMN($Y$16)+1)} -> 1433433.6 | R18: {=INDEX('Proj. Vendas MUVX Digital'!$Y$65:$Y$73, COLUMN(AF16)-COLUMN($Y$16)+1)} -> 2106828.2 | S18: {=INDEX('Proj. Vendas MUVX Digital'!$Y$65:$Y$73, COLUMN(AG16)-COLUMN($Y$16)+1)} -> 2248062.1 | T18: =SUM(H18:S18) -> 7939913.7
A19: Receita MUVX Digital (Alunos) Fee - Realizado | B19: 0 | C19: 0 | D19: 0 | E19: 0 | F19: 0 | G19: 0 | H19: 0 | I19: 0 | J19: 0 | K19: 0 | L19: 0 | M19: 0 | N19: 0 | O19: 0 | P19: 0 | Q19: 0 | R19: 0 | S19: 0 | T19: =SUM(H19:S19) -> 0
A20: Receita Não Recorrente | B20: =SUM(B21:B24) -> 0 | C20: =SUM(C21:C24) -> 0 | D20: =SUM(D21:D24) -> 0 | E20: =SUM(E21:E24) -> 0 | F20: =SUM(F21:F24) -> 0 | G20: =SUM(G21:G24) -> 0 | H20: =SUM(H21:H24) -> 0 | I20: =SUM(I21:I24) -> 0 | ... S20: =SUM(S21:S24) -> 0 | T20: =SUM(H20:S20) -> 0
A21: Patrocínio Eventos - Estimado | B21: 0 | C21: 0 | D21: 0 | E21: 0 | F21: 0 | G21: 0 | H21: 0 | I21: 0 | J21: 0 | K21: 0 | L21: 0 | M21: 0 | N21: 0 | O21: 0 | P21: 0 | Q21: 0 | R21: 0 | S21: 0 | T21: =SUM(H21:S21) -> 0
A22: Patrocínio Eventos - Realizado | B22: 0 | C22: 0 | D22: 0 | E22: 0 | F22: 0 | G22: 0 | H22: 0 | I22: 0 | J22: 0 | K22: 0 | L22: 0 | M22: 0 | N22: 0 | O22: 0 | P22: 0 | Q22: 0 | R22: 0 | S22: 0 | T22: =SUM(H22:S22) -> 0
A23: Receita Eventos - Estimado | B23: 0 | C23: 0 | D23: 0 | E23: 0 | F23: 0 | G23: 0 | H23: 0 | I23: 0 | J23: 0 | K23: 0 | L23: 0 | M23: 0 | N23: 0 | O23: 0 | P23: 0 | Q23: 0 | R23: 0 | S23: 0 | T23: =SUM(H23:S23) -> 0
A24: Receita Eventos - Realizado | B24: 0 | C24: 0 | D24: 0 | E24: 0 | F24: 0 | G24: 0 | H24: 0 | I24: 0 | J24: 0 | K24: 0 | L24: 0 | M24: 0 | N24: 0 | O24: 0 | P24: 0 | Q24: 0 | R24: 0 | S24: 0 | T24: =SUM(H24:S24) -> 0
A25: Saídas Operacionais | B25: =B26+B76+B86+B142 -> 0 | C25: =C26+C76+C86+C142 -> 3887.33 | D25: =D26+D76+D86+D142 -> 73368.93 | E25: =E26+E76+E86+E142 -> 165876.82 | F25: =F26+F76+F86+F142 -> 217155.82 | G25: =G26+G76+G86+G142 -> 211330.67 | H25: =H26+H76+H86+H142 -> 222684.31 | I25: =I26+I76+I86+I142 -> 215511.17 | ... S25: =S26+S76+S86+S142 -> 1782652.5 | T25: =SUM(H25:S25) -> 8242464.2
A26: Custos Fixos Operacionais | B26: =B27+B34+B37+B68 -> 0 | C26: =C27+C34+C37+C68 -> 3637.33 | D26: =D27+D34+D37+D68 -> 71613.93 | E26: =E27+E34+E37+E68 -> 111603.38 | F26: =F27+F34+F37+F68 -> 136259.63 | G26: =G27+G34+G37+G68 -> 156573.31 | H26: =H27+H34+H37+H68 -> 145929.15 | I26: =I27+I34+I37+I68 -> 173607.66 | ... S26: =S27+S34+S37+S68 -> 484218.94 | T26: =SUM(H26:S26) -> 2892038
A27: Custos com pessoal | B27: =SUM(B28:B33) -> 0 | C27: =SUM(C28:C33) -> 0 | D27: =SUM(D28:D33) -> 66667.12 | E27: =SUM(E28:E33) -> 82399.38 | F27: =SUM(F28:F33) -> 105680.58 | G27: =SUM(G28:G33) -> 109604.61 | H27: =SUM(H28:H33) -> 111812.77 | I27: =SUM(I28:I33) -> 141622.32 | ... S27: =SUM(S28:S33) -> 399911.28 | T27: =SUM(H27:S27) -> 2251114.3
A28: Gympass/Wellhub | E28: 1447.9 | G28: 3061 | I28: 1326.44 | J28: 1224.41 | K28: 1000 | L28: =K28*1.1 -> 1100 | M28: =L28*1.2 -> 1320 | N28: =M28*1.2 -> 1584 | O28: =N28*1.3 -> 2059.2 | P28: =O28*1.3 -> 2676.96 | Q28: =P28*1.3 -> 3480.048 | R28: =Q28*1.3 -> 4524.0624 | S28: =R28*1.3 -> 5881.2811 | T28: =SUM(H28:S28) -> 26176.402
A29: Salários | B29: 0 | C29: 0 | D29: 66667.12 | E29: 80951.48 | F29: 101227.58 | G29: 106458.61 | H29: 111812.77 | I29: 140295.88 | J29: 135000 | K29: 115000 | L29: 90000 | M29: =L29*1.1 -> 99000 | N29: =M29*1.1 -> 108900 | O29: =N29*1.2 -> 130680 | P29: =O29*1.2 -> 156816 | Q29: =P29*1.2 -> 188179.2 | R29: =Q29*1.25 -> 235224 | S29: =R29*1.25 -> 294030 | T29: =SUM(H29:S29) -> 1804937.9
A30: Salário CEO | O30: 60000 | P30: 60000 | Q30: 100000 | R30: 100000 | S30: 100000 | T30: =SUM(H30:S30) -> 420000
A31: Gerar (estágio) | F31: 85 | G31: 85 | T31: =SUM(H31:S31) -> 0
A32: Férias | T32: =SUM(H32:S32) -> 0
A33: Ajuda de Custo Presencial | F33: 4368 | T33: =SUM(H33:S33) -> 0
A34: Infraestrutura | B34: =SUM(B35:B36) -> 0 | C34: =SUM(C35:C36) -> 0 | D34: =SUM(D35:D36) -> 0 | E34: =SUM(E35:E36) -> 4360 | F34: =SUM(F35:F36) -> 0 | G34: =SUM(G35:G36) -> 14560 | H34: =SUM(H35:H36) -> 0 | I34: =SUM(I35:I36) -> 0 | ... S34: =SUM(S35:S36) -> 45000 | T34: =SUM(H34:S34) -> 284560
A35: Escritorio | E35: 4360 | G35: 14560 | K35: =14560 -> 14560 | N35: 20000 | O35: 20000 | P35: 20000 | Q35: 20000 | R35: 20000 | S35: 20000 | T35: =SUM(H35:S35) -> 134560
A36: Base Executiva SP | N36: 25000 | O36: 25000 | P36: 25000 | Q36: 25000 | R36: 25000 | S36: 25000 | T36: =SUM(H36:S36) -> 150000
A37: Software + Equipamentos | B37: =SUM(B38:B67) -> 0 | C37: =SUM(C38:C67) -> 440.33 | D37: =SUM(D38:D67) -> 1145.94 | E37: =SUM(E38:E67) -> 8692.72 | F37: =SUM(F38:F67) -> 8355.65 | G37: =SUM(G38:G67) -> 10249.7 | H37: =SUM(H38:H67) -> 17704.38 | I37: =SUM(I38:I67) -> 15170.34 | ... S37: =SUM(S38:S67) -> 21592.664 | T37: =SUM(H37:S37) -> 185986.72
A38: Office365 | D38: 560 | E38: 1869.32 | F38: 0 | G38: 4171.2 | H38: 2980.32 | I38: =2921.48+48.08 -> 2969.56 | J38: =2921.48 -> 2921.48 | K38: 1962.45 | L38: 600 | M38: =L38*1.2 -> 720 | N38: =M38*1.2 -> 864 | O38: =N38*1.3 -> 1123.2 | P38: =O38*1.3 -> 1460.16 | Q38: =P38*1.3 -> 1898.208 | R38: =Q38*1.3 -> 2467.6704 | S38: =R38*1.3 -> 3207.9715 | T38: =SUM(H38:S38) -> 23175.02
A39: Equipamentos | E39: 273.95 | F39: 273.95 | G39: 954.34 | H39: 2135.76 | I39: 273.95 | J39: 273.95 | K39: 273.95 | L39: 273.95 | M39: 273.95 | T39: =SUM(H39:S39) -> 3505.51
A40: Equipamentos - Transferência de Ativos | I40: =383.33+283.42+287.59+633.52 -> 1587.86 | J40: 670.92 | K40: 670.92 | L40: 287.59 | T40: =SUM(H40:S40) -> 3217.29
...

Sheet Proj. Vendas MUVX Core New
C1: Top | E1: Install | G1: Ativação | I1: Conversão | N1: Cenário sem perdas operacionais | X1: Cenário com perdas operacionais
A2: Mês | B2: Investimento no Mês (Growth) // 5% | C2: CPL - Tráfego (cadastro) | D2: Novos Cadastros LP | E2: Tx. % Install | F2: Novos Installs no App | G2: Tx % Ativações | H2: Novos Personais Habilitados | I2: Tx % de Conversão | J2: Cadastros Evento Presencial | K2: Tx % Ativação Presencial | L2: Novos Personais Ativados | M2: Personais Totais | N2: CAC (ativação) | O2: Tx. % Churn | P2: Qtde. Churn no Mês | Q2: Personais Ativos Mês | R2: Média Alunos Estimada Total Personal | S2: Ticket Médio Aluno Personal | T2: Média Faturamento Estimada Personal | U2: Total Usuários Estimado | V2: Faturamento Estimado | W2: Receita MUVX Estimada (2%) | X2: Média Real Alunos Ativos Personal | Y2: Tx. % Real Alunos não ativados | Z2: Média Real por Personal | AA2: Total Real Usuários | AB2: Faturamento Real Bruto | AC2: Receita MUVX (2%) | AD2: Faturamento Real Acumulado | AE2: Receita MUVX Acumulada | AF2: Investimento Acumulado | AG2: ROI | AH2: ROI Acumulado
A3: 46023 | B3: =B64*0.05 -> 1566.913 | C3: =C64 -> 12 | D3: =Table15313[[#This Row],[Investimento no Mês (Growth) // 5%]]/Table15313[[#This Row],[CPL - Tráfego (cadastro)]] -> 130.57608 | E3: =E64 -> 0.06 | F3: =Table15313[[#This Row],[Novos Cadastros LP]]*Table15313[[#This Row],[Tx. % Install]] -> 7.834565 | G3: =G64 -> 0 | H3: =Table15313[[#This Row],[Novos Installs no App]]*Table15313[[#This Row],[Tx % Ativações]] -> 0 | I3: =I64 -> 0.7 | J3: =J64*20% -> 0 | K3: =K64 -> 0 | L3: =(Table15313[[#This Row],[Novos Personais Habilitados]]*Table15313[[#This Row],[Tx % de Conversão]])+(Table15313[[#This Row],[Cadastros Evento Presencial]]*Table15313[[#This Row],[Tx % Ativação Presencial]]) -> 0 | M3: =Table15313[[#This Row],[Novos Personais Ativados]] -> 0 | N3: =Table15313[[#This Row],[Investimento no Mês (Growth) // 5%]]/Table15313[[#This Row],[Novos Personais Ativados]] -> #DIV/0! | O3: 0 | P3: =Table15313[[#This Row],[Personais Totais]]*Table15313[[#This Row],[Tx. % Churn]] -> 0 | Q3: =Table15313[[#This Row],[Personais Totais]]-Table15313[[#This Row],[Qtde. Churn no Mês]] -> 0 | R3: 15 | S3: 0 | T3: 0 | U3: =Table15313[[#This Row],[Personais Ativos Mês]]+(Table15313[[#This Row],[Personais Ativos Mês]]*Table15313[[#This Row],[Média Alunos Estimada Total Personal]]) -> 0 | V3: 0 | W3: =Table15313[[#This Row],[Faturamento Estimado]]*2% -> 0 | X3: =Table15313[[#This Row],[Média Alunos Estimada Total Personal]]-(Table15313[[#This Row],[Tx. % Real Alunos não ativados]]*Table15313[[#This Row],[Média Alunos Estimada Total Personal]]) -> 9.75 | Y3: 0.35 | Z3: =AB3/Q3 -> #DIV/0! | AA3: =Table15313[[#This Row],[Média Real Alunos Ativos Personal]]*Table15313[[#This Row],[Personais Ativos Mês]] -> 0 | AB3: 0 | AC3: 0 | AD3: =Table15313[[#This Row],[Faturamento Real Bruto]] -> 0 | AE3: 0 | AF3: =Table15313[[#This Row],[Investimento no Mês (Growth) // 5%]] -> 1566.913 | AG3: 0 | AH3: 0
A4: 46054 | B4: =B65*0.05 -> 264.6285 | C4: =C65 -> 14 | D4: 1031 | E4: =E65 -> 0.2 | F4: =Table15313[[#This Row],[Novos Cadastros LP]]*Table15313[[#This Row],[Tx. % Install]] -> 206.2 | G4: =G65 -> 0.5 | H4: =Table15313[[#This Row],[Novos Installs no App]]*Table15313[[#This Row],[Tx % Ativações]] -> 103.1 | I4: =I65 -> 0.3 | J4: =J65*20% -> 0 | K4: =K65 -> 0 | L4: =(Table15313[[#This Row],[Novos Personais Habilitados]]*Table15313[[#This Row],[Tx % de Conversão]])+(Table15313[[#This Row],[Cadastros Evento Presencial]]*Table15313[[#This Row],[Tx % Ativação Presencial]]) -> 30.93 | M4: =Table15313[[#This Row],[Novos Personais Ativados]]+M3 -> 30.93 | N4: =Table15313[[#This Row],[Investimento no Mês (Growth) // 5%]]/Table15313[[#This Row],[Novos Personais Ativados]] -> 8.5557226 | O4: 0.02 | P4: =M3*Table15313[[#This Row],[Tx. % Churn]] -> 0 | Q4: =Table15313[[#This Row],[Personais Totais]]-Table15313[[#This Row],[Qtde. Churn no Mês]] -> 30.93 | R4: 15 | S4: 250 | T4: =Table15313[[#This Row],[Média Alunos Estimada Total Personal]]*Table15313[[#This Row],[Ticket Médio Aluno Personal]] -> 3750 | U4: =Table15313[[#This Row],[Personais Ativos Mês]]+(Table15313[[#This Row],[Personais Ativos Mês]]*Table15313[[#This Row],[Média Alunos Estimada Total Personal]]) -> 494.88 | V4: =Table15313[[#This Row],[Média Faturamento Estimada Personal]]*Q3 -> 0 | W4: =Table15313[[#This Row],[Faturamento Estimado]]*2% -> 0 | X4: =Table15313[[#This Row],[Média Alunos Estimada Total Personal]]-(Table15313[[#This Row],[Tx. % Real Alunos não ativados]]*Table15313[[#This Row],[Média Alunos Estimada Total Personal]]) -> 4.5 | Y4: 0.7 | Z4: =Table15313[[#This Row],[Ticket Médio Aluno Personal]]*Table15313[[#This Row],[Média Real Alunos Ativos Personal]] -> 1125 | AA4: =Table15313[[#This Row],[Média Real Alunos Ativos Personal]]*Table15313[[#This Row],[Personais Ativos Mês]] -> 139.185 | AB4: =Table15313[[#This Row],[Média Real por Personal]]*Q3 -> 0 | AC4: =Table15313[[#This Row],[Faturamento Real Bruto]]*2% -> 0 | AD4: =Table15313[[#This Row],[Faturamento Real Bruto]]+AB3 -> 0 | AE4: =Table15313[[#This Row],[Receita MUVX (2%)]]+AC3 -> 0 | AF4: =Table15313[[#This Row],[Investimento no Mês (Growth) // 5%]]+AF3 -> 1831.5415 | AG4: =Table15313[[#This Row],[Receita MUVX Acumulada]]/Table15313[[#This Row],[Investimento Acumulado]] -> 0 | AH4: =Table15313[[#This Row],[ROI]]+AH3 -> 0
A5: 46082 | B5: =B66*0.05 -> 50 | C5: =C66 -> 13.86 | D5: =Table15313[[#This Row],[Investimento no Mês (Growth) // 5%]]/Table15313[[#This Row],[CPL - Tráfego (cadastro)]] -> 3.6075036 | E5: =E66 -> 0.2 | F5: =Table15313[[#This Row],[Novos Cadastros LP]]*Table15313[[#This Row],[Tx. % Install]] -> 0.72150072 | G5: =G66 -> 0.5 | H5: =Table15313[[#This Row],[Novos Installs no App]]*Table15313[[#This Row],[Tx % Ativações]] -> 0.36075036 | I5: =I66 -> 0.3 | J5: =J66*20% -> 0 | K5: =K66 -> 0 | L5: =(Table15313[[#This Row],[Novos Personais Habilitados]]*Table15313[[#This Row],[Tx % de Conversão]])+(Table15313[[#This Row],[Cadastros Evento Presencial]]*Table15313[[#This Row],[Tx % Ativação Presencial]]) -> 0.10822511 | M5: =Table15313[[#This Row],[Novos Personais Ativados]]+M4 -> 31.038225 | N5: =Table15313[[#This Row],[Investimento no Mês (Growth) // 5%]]/Table15313[[#This Row],[Novos Personais Ativados]] -> 462 | O5: 0.03 | P5: =M4*Table15313[[#This Row],[Tx. % Churn]] -> 0.9279 | Q5: =Table15313[[#This Row],[Personais Totais]]-Table15313[[#This Row],[Qtde. Churn no Mês]] -> 30.110325 | R5: 15 | S5: =S4*1.005 -> 251.25 | T5: =Table15313[[#This Row],[Média Alunos Estimada Total Personal]]*Table15313[[#This Row],[Ticket Médio Aluno Personal]] -> 3768.75 | U5: =Table15313[[#This Row],[Personais Ativos Mês]]+(Table15313[[#This Row],[Personais Ativos Mês]]*Table15313[[#This Row],[Média Alunos Estimada Total Personal]]) -> 481.7652 | V5: =Table15313[[#This Row],[Média Faturamento Estimada Personal]]*Q4 -> 116567.44 | W5: =Table15313[[#This Row],[Faturamento Estimado]]*2% -> 2331.3487 | X5: =Table15313[[#This Row],[Média Alunos Estimada Total Personal]]-(Table15313[[#This Row],[Tx. % Real Alunos não ativados]]*Table15313[[#This Row],[Média Alunos Estimada Total Personal]]) -> 14.25 | Y5: 0.05 | Z5: =Table15313[[#This Row],[Ticket Médio Aluno Personal]]*Table15313[[#This Row],[Média Real Alunos Ativos Personal]] -> 3580.3125 | AA5: =Table15313[[#This Row],[Média Real Alunos Ativos Personal]]*Table15313[[#This Row],[Personais Ativos Mês]] -> 429.07213 | AB5: =Table15313[[#This Row],[Média Real por Personal]]*Q4 -> 110739.07 | AC5: =Table15313[[#This Row],[Faturamento Real Bruto]]*2% -> 2214.7813 | AD5: =AD4+Table15313[[#This Row],[Faturamento Real Bruto]] -> 110739.07 | AE5: =AE4+Table15313[[#This Row],[Receita MUVX (2%)]] -> 2214.7813 | AF5: =Table15313[[#This Row],[Investimento no Mês (Growth) // 5%]]+AF4 -> 1881.5415 | AG5: =Table15313[[#This Row],[Receita MUVX Acumulada]]/Table15313[[#This Row],[Investimento Acumulado]] -> 1.17711 | AH5: =Table15313[[#This Row],[ROI]]+AH4 -> 1.17711
A6: 46113 | B6: =B67*0.05 -> 50 | C6: =C67 -> 13.7214 | D6: =Table15313[[#This Row],[Investimento no Mês (Growth) // 5%]]/Table15313[[#This Row],[CPL - Tráfego (cadastro)]] -> 3.643943 | E6: =E67 -> 0.2 | F6: =Table15313[[#This Row],[Novos Cadastros LP]]*Table15313[[#This Row],[Tx. % Install]] -> 0.72878861 | G6: =G67 -> 0.5 | H6: =Table15313[[#This Row],[Novos Installs no App]]*Table15313[[#This Row],[Tx % Ativações]] -> 0.3643943 | I6: =I67 -> 0.3 | J6: =J67*20% -> 0 | K6: =K67 -> 0 | L6: =(Table15313[[#This Row],[Novos Personais Habilitados]]*Table15313[[#This Row],[Tx % de Conversão]])+(Table15313[[#This Row],[Cadastros Evento Presencial]]*Table15313[[#This Row],[Tx % Ativação Presencial]]) -> 0.10931829 | M6: =Table15313[[#This Row],[Novos Personais Ativados]]+M5 -> 31.147543 | N6: =Table15313[[#This Row],[Investimento no Mês (Growth) // 5%]]/Table15313[[#This Row],[Novos Personais Ativados]] -> 457.38 | O6: 0.02 | P6: =M5*Table15313[[#This Row],[Tx. % Churn]] -> 0.6207645 | Q6: =Table15313[[#This Row],[Personais Totais]]-Table15313[[#This Row],[Qtde. Churn no Mês]] -> 30.526779 | R6: 15 | S6: =S5*1.015 -> 255.01875 | T6: =Table15313[[#This Row],[Média Alunos Estimada Total Personal]]*Table15313[[#This Row],[Ticket Médio Aluno Personal]] -> 3825.2812 | U6: =Table15313[[#This Row],[Personais Ativos Mês]]+(Table15313[[#This Row],[Personais Ativos Mês]]*Table15313[[#This Row],[Média Alunos Estimada Total Personal]]) -> 488.42846 | V6: =Table15313[[#This Row],[Média Faturamento Estimada Personal]]*Q5 -> 115180.46 | W6: =Table15313[[#This Row],[Faturamento Estimado]]*2% -> 2303.6092 | X6: =Table15313[[#This Row],[Média Alunos Estimada Total Personal]]-(Table15313[[#This Row],[Tx. % Real Alunos não ativados]]*Table15313[[#This Row],[Média Alunos Estimada Total Personal]]) -> 14.25 | Y6: 0.05 | Z6: =Table15313[[#This Row],[Ticket Médio Aluno Personal]]*Table15313[[#This Row],[Média Real Alunos Ativos Personal]] -> 3634.0172 | AA6: =Table15313[[#This Row],[Média Real Alunos Ativos Personal]]*Table15313[[#This Row],[Personais Ativos Mês]] -> 435.0066 | AB6: =Table15313[[#This Row],[Média Real por Personal]]*Q5 -> 109421.44 | AC6: =Table15313[[#This Row],[Faturamento Real Bruto]]*2% -> 2188.4288 | AD6: =AD5+Table15313[[#This Row],[Faturamento Real Bruto]] -> 220160.5 | AE6: =AE5+Table15313[[#This Row],[Receita MUVX (2%)]] -> 4403.2101 | AF6: =Table15313[[#This Row],[Investimento no Mês (Growth) // 5%]]+AF5 -> 1931.5415 | AG6: =Table15313[[#This Row],[Receita MUVX Acumulada]]/Table15313[[#This Row],[Investimento Acumulado]] -> 2.2796353 | AH6: =Table15313[[#This Row],[ROI]]+AH5 -> 3.4567452
A7: 46143 | B7: =B68*0.05 -> 250 | C7: =C68 -> 13.584186 | D7: =Table15313[[#This Row],[Investimento no Mês (Growth) // 5%]]/Table15313[[#This Row],[CPL - Tráfego (cadastro)]] -> 18.403753 | E7: =E68 -> 0.2 | F7: =Table15313[[#This Row],[Novos Cadastros LP]]*Table15313[[#This Row],[Tx. % Install]] -> 3.6807505 | G7: =G68 -> 0.6 | H7: =Table15313[[#This Row],[Novos Installs no App]]*Table15313[[#This Row],[Tx % Ativações]] -> 2.2084503 | I7: =I68 -> 0.3 | J7: =J68*20% -> 0 | K7: =K68 -> 0 | L7: =(Table15313[[#This Row],[Novos Personais Habilitados]]*Table15313[[#This Row],[Tx % de Conversão]])+(Table15313[[#This Row],[Cadastros Evento Presencial]]*Table15313[[#This Row],[Tx % Ativação Presencial]]) -> 0.6625351 | M7: =Table15313[[#This Row],[Novos Personais Ativados]]+M6 -> 31.810078 | N7: =Table15313[[#This Row],[Investimento no Mês (Growth) // 5%]]/Table15313[[#This Row],[Novos Personais Ativados]] -> 377.3385 | O7: 0.02 | P7: =M6*Table15313[[#This Row],[Tx. % Churn]] -> 0.62295087 | Q7: =Table15313[[#This Row],[Personais Totais]]-Table15313[[#This Row],[Qtde. Churn no Mês]] -> 31.187128 | R7: 15 | S7: =S6*1.015 -> 258.84403 | T7: =Table15313[[#This Row],[Média Alunos Estimada Total Personal]]*Table15313[[#This Row],[Ticket Médio Aluno Personal]] -> 3882.6605 | U7: =Table15313[[#This Row],[Personais Ativos Mês]]+(Table15313[[#This Row],[Personais Ativos Mês]]*Table15313[[#This Row],[Média Alunos Estimada Total Personal]]) -> 498.99404 | V7: =Table15313[[#This Row],[Média Faturamento Estimada Personal]]*Q6 -> 118525.12 | W7: =Table15313[[#This Row],[Faturamento Estimado]]*2% -> 2370.5024 | X7: =Table15313[[#This Row],[Média Alunos Estimada Total Personal]]-(Table15313[[#This Row],[Tx. % Real Alunos não ativados]]*Table15313[[#This Row],[Média Alunos Estimada Total Personal]]) -> 14.25 | Y7: 0.05 | Z7: =Table15313[[#This Row],[Ticket Médio Aluno Personal]]*Table15313[[#This Row],[Média Real Alunos Ativos Personal]] -> 3688.5274 | AA7: =Table15313[[#This Row],[Média Real Alunos Ativos Personal]]*Table15313[[#This Row],[Personais Ativos Mês]] -> 444.41657 | AB7: =Table15313[[#This Row],[Média Real por Personal]]*Q6 -> 112598.86 | AC7: =Table15313[[#This Row],[Faturamento Real Bruto]]*2% -> 2251.9772 | AD7: =AD6+Table15313[[#This Row],[Faturamento Real Bruto]] -> 332759.37 | AE7: =AE6+Table15313[[#This Row],[Receita MUVX (2%)]] -> 6655.1873 | AF7: =Table15313[[#This Row],[Investimento no Mês (Growth) // 5%]]+AF6 -> 2181.5415 | AG7: =Table15313[[#This Row],[Receita MUVX Acumulada]]/Table15313[[#This Row],[Investimento Acumulado]] -> 3.0506811 | AH7: =Table15313[[#This Row],[ROI]]+AH6 -> 6.5074263
A8: 46174 | B8: =B69*0.05 -> 1500 | C8: =C69 -> 13.448344 | D8: =Table15313[[#This Row],[Investimento no Mês (Growth) // 5%]]/Table15313[[#This Row],[CPL - Tráfego (cadastro)]] -> 111.5379 | E8: 0.3 | F8: =Table15313[[#This Row],[Novos Cadastros LP]]*Table15313[[#This Row],[Tx. % Install]] -> 33.461369 | G8: =G69 -> 0.6 | H8: =Table15313[[#This Row],[Novos Installs no App]]*Table15313[[#This Row],[Tx % Ativações]] -> 20.076821 | I8: =I69 -> 0.3 | J8: =J69*20% -> 0 | K8: =K69 -> 0 | L8: =(Table15313[[#This Row],[Novos Personais Habilitados]]*Table15313[[#This Row],[Tx % de Conversão]])+(Table15313[[#This Row],[Cadastros Evento Presencial]]*Table15313[[#This Row],[Tx % Ativação Presencial]]) -> 6.0230463 | M8: =Table15313[[#This Row],[Novos Personais Ativados]]+M7 -> 37.833125 | N8: =Table15313[[#This Row],[Investimento no Mês (Growth) // 5%]]/Table15313[[#This Row],[Novos Personais Ativados]] -> 249.04341 | O8: 0.04 | P8: =M7*Table15313[[#This Row],[Tx. % Churn]] -> 1.2724031 | Q8: =Table15313[[#This Row],[Personais Totais]]-Table15313[[#This Row],[Qtde. Churn no Mês]] -> 36.560722 | R8: 15 | S8: =S7*1.015 -> 262.72669 | T8: =Table15313[[#This Row],[Média Alunos Estimada Total Personal]]*Table15313[[#This Row],[Ticket Médio Aluno Personal]] -> 3940.9004 | U8: =Table15313[[#This Row],[Personais Ativos Mês]]+(Table15313[[#This Row],[Personais Ativos Mês]]*Table15313[[#This Row],[Média Alunos Estimada Total Personal]]) -> 584.97155 | V8: =Table15313[[#This Row],[Média Faturamento Estimada Personal]]*Q7 -> 122905.36 | W8: =Table15313[[#This Row],[Faturamento Estimado]]*2% -> 2458.1073 | X8: =Table15313[[#This Row],[Média Alunos Estimada Total Personal]]-(Table15313[[#This Row],[Tx. % Real Alunos não ativados]]*Table15313[[#This Row],[Média Alunos Estimada Total Personal]]) -> 14.25 | Y8: 0.05 | Z8: =Table15313[[#This Row],[Ticket Médio Aluno Personal]]*Table15313[[#This Row],[Média Real Alunos Ativos Personal]] -> 3743.8554 | AA8: =Table15313[[#This Row],[Média Real Alunos Ativos Personal]]*Table15313[[#This Row],[Personais Ativos Mês]] -> 520.99028 | AB8: =Table15313[[#This Row],[Média Real por Personal]]*Q7 -> 116760.09 | AC8: =Table15313[[#This Row],[Faturamento Real Bruto]]*2% -> 2335.2019 | AD8: =AD7+Table15313[[#This Row],[Faturamento Real Bruto]] -> 449519.46 | AE8: =AE7+Table15313[[#This Row],[Receita MUVX (2%)]] -> 8990.3892 | AF8: =Table15313[[#This Row],[Investimento no Mês (Growth) // 5%]]+AF7 -> 3681.5415 | AG8: =Table15313[[#This Row],[Receita MUVX Acumulada]]/Table15313[[#This Row],[Investimento Acumulado]] -> 2.4420176 | AH8: =Table15313[[#This Row],[ROI]]+AH7 -> 8.9494439
A9: 46204 | B9: =B70*0.05 -> 5000 | C9: =C70 -> 13.313861 | D9: =Table15313[[#This Row],[Investimento no Mês (Growth) // 5%]]/Table15313[[#This Row],[CPL - Tráfego (cadastro)]] -> 375.54847 | E9: =E70 -> 0.3 | F9: =Table15313[[#This Row],[Novos Cadastros LP]]*Table15313[[#This Row],[Tx. % Install]] -> 112.66454 | G9: =G70 -> 0.6 | H9: =Table15313[[#This Row],[Novos Installs no App]]*Table15313[[#This Row],[Tx % Ativações]] -> 67.598724 | I9: =I70 -> 0.3 | J9: =J70*20% -> 0 | K9: =K70 -> 0.2 | L9: =(Table15313[[#This Row],[Novos Personais Habilitados]]*Table15313[[#This Row],[Tx % de Conversão]])+(Table15313[[#This Row],[Cadastros Evento Presencial]]*Table15313[[#This Row],[Tx % Ativação Presencial]]) -> 20.279617 | M9: =Table15313[[#This Row],[Novos Personais Ativados]]+M8 -> 58.112742 | N9: =Table15313[[#This Row],[Investimento no Mês (Growth) // 5%]]/Table15313[[#This Row],[Novos Personais Ativados]] -> 246.55298 | O9: 0.02 | P9: =M8*Table15313[[#This Row],[Tx. % Churn]] -> 0.7566625 | Q9: =Table15313[[#This Row],[Personais Totais]]-Table15313[[#This Row],[Qtde. Churn no Mês]] -> 57.35608 | R9: 15 | S9: =S8*1.015 -> 266.66759 | T9: =Table15313[[#This Row],[Média Alunos Estimada Total Personal]]*Table15313[[#This Row],[Ticket Médio Aluno Personal]] -> 4000.0139 | U9: =Table15313[[#This Row],[Personais Ativos Mês]]+(Table15313[[#This Row],[Personais Ativos Mês]]*Table15313[[#This Row],[Média Alunos Estimada Total Personal]]) -> 917.69727 | V9: =Table15313[[#This Row],[Média Faturamento Estimada Personal]]*Q8 -> 146243.39 | W9: =Table15313[[#This Row],[Faturamento Estimado]]*2% -> 2924.8679 | X9: =Table15313[[#This Row],[Média Alunos Estimada Total Personal]]-(Table15313[[#This Row],[Tx. % Real Alunos não ativados]]*Table15313[[#This Row],[Média Alunos Estimada Total Personal]]) -> 14.25 | Y9: 0.05 | Z9: =Table15313[[#This Row],[Ticket Médio Aluno Personal]]*Table15313[[#This Row],[Média Real Alunos Ativos Personal]] -> 3800.0132 | AA9: =Table15313[[#This Row],[Média Real Alunos Ativos Personal]]*Table15313[[#This Row],[Personais Ativos Mês]] -> 817.32414 | AB9: =Table15313[[#This Row],[Média Real por Personal]]*Q8 -> 138931.22 | AC9: =Table15313[[#This Row],[Faturamento Real Bruto]]*2% -> 2778.6245 | AD9: =AD8+Table15313[[#This Row],[Faturamento Real Bruto]] -> 588450.69 | AE9: =AE8+Table15313[[#This Row],[Receita MUVX (2%)]] -> 11769.014 | AF9: =Table15313[[#This Row],[Investimento no Mês (Growth) // 5%]]+AF8 -> 8681.5415 | AG9: =Table15313[[#This Row],[Receita MUVX Acumulada]]/Table15313[[#This Row],[Investimento Acumulado]] -> 1.3556364 | AH9: =Table15313[[#This Row],[ROI]]+AH8 -> 10.30508
A10: 46235 | B10: =B71*0.05 -> 5000 | C10: =C71 -> 13.180722 | D10: =Table15313[[#This Row],[Investimento no Mês (Growth) // 5%]]/Table15313[[#This Row],[CPL - Tráfego (cadastro)]] -> 379.34189 | E10: =E71 -> 0.3 | F10: =Table15313[[#This Row],[Novos Cadastros LP]]*Table15313[[#This Row],[Tx. % Install]] -> 113.80257 | G10: =G71 -> 0.6 | H10: =Table15313[[#This Row],[Novos Installs no App]]*Table15313[[#This Row],[Tx % Ativações]] -> 68.28154 | I10: =I71 -> 0.3 | J10: =J71*20% -> 0 | K10: =K71 -> 0 | L10: =(Table15313[[#This Row],[Novos Personais Habilitados]]*Table15313[[#This Row],[Tx % de Conversão]])+(Table15313[[#This Row],[Cadastros Evento Presencial]]*Table15313[[#This Row],[Tx % Ativação Presencial]]) -> 20.484462 | M10: =Table15313[[#This Row],[Novos Personais Ativados]]+M9 -> 78.597204 | N10: =Table15313[[#This Row],[Investimento no Mês (Growth) // 5%]]/Table15313[[#This Row],[Novos Personais Ativados]] -> 244.08745 | O10: 0.02 | P10: =M9*Table15313[[#This Row],[Tx. % Churn]] -> 1.1622548 | Q10: =Table15313[[#This Row],[Personais Totais]]-Table15313[[#This Row],[Qtde. Churn no Mês]] -> 77.434949 | R10: 15 | S10: =S9*1.015 -> 270.66761 | T10: =Table15313[[#This Row],[Média Alunos Estimada Total Personal]]*Table15313[[#This Row],[Ticket Médio Aluno Personal]] -> 4060.0141 | U10: =Table15313[[#This Row],[Personais Ativos Mês]]+(Table15313[[#This Row],[Personais Ativos Mês]]*Table15313[[#This Row],[Média Alunos Estimada Total Personal]]) -> 1238.9592 | V10: =Table15313[[#This Row],[Média Faturamento Estimada Personal]]*Q9 -> 232866.49 | W10: =Table15313[[#This Row],[Faturamento Estimado]]*2% -> 4657.3298 | X10: =Table15313[[#This Row],[Média Alunos Estimada Total Personal]]-(Table15313[[#This Row],[Tx. % Real Alunos não ativados]]*Table15313[[#This Row],[Média Alunos Estimada Total Personal]]) -> 14.25 | Y10: 0.05 | Z10: =Table15313[[#This Row],[Ticket Médio Aluno Personal]]*Table15313[[#This Row],[Média Real Alunos Ativos Personal]] -> 3857.0134 | AA10: =Table15313[[#This Row],[Média Real Alunos Ativos Personal]]*Table15313[[#This Row],[Personais Ativos Mês]] -> 1103.448 | AB10: =Table15313[[#This Row],[Média Real por Personal]]*Q9 -> 221223.17 | AC10: =Table15313[[#This Row],[Faturamento Real Bruto]]*2% -> 4424.4633 | AD10: =AD9+Table15313[[#This Row],[Faturamento Real Bruto]] -> 809673.85 | AE10: =AE9+Table15313[[#This Row],[Receita MUVX (2%)]] -> 16193.477 | AF10: =Table15313[[#This Row],[Investimento no Mês (Growth) // 5%]]+AF9 -> 13681.541 | AG10: =Table15313[[#This Row],[Receita MUVX Acumulada]]/Table15313[[#This Row],[Investimento Acumulado]] -> 1.1836003 | AH10: =Table15313[[#This Row],[ROI]]+AH9 -> 11.488681
A11: 46266 | B11: =B72*0.05 -> 5000 | C11: =C72 -> 13.048915 | D11: =Table15313[[#This Row],[Investimento no Mês (Growth) // 5%]]/Table15313[[#This Row],[CPL - Tráfego (cadastro)]] -> 383.17362 | E11: =E72 -> 0.3 | F11: =Table15313[[#This Row],[Novos Cadastros LP]]*Table15313[[#This Row],[Tx. % Install]] -> 114.95209 | G11: =G72 -> 0.6 | H11: =Table15313[[#This Row],[Novos Installs no App]]*Table15313[[#This Row],[Tx % Ativações]] -> 68.971252 | I11: =I72 -> 0.3 | J11: =J72*20% -> 0 | K11: =K72 -> 0 | L11: =(Table15313[[#This Row],[Novos Personais Habilitados]]*Table15313[[#This Row],[Tx % de Conversão]])+(Table15313[[#This Row],[Cadastros Evento Presencial]]*Table15313[[#This Row],[Tx % Ativação Presencial]]) -> 20.691376 | M11: =Table15313[[#This Row],[Novos Personais Ativados]]+M10 -> 99.28858 | N11: =Table15313[[#This Row],[Investimento no Mês (Growth) // 5%]]/Table15313[[#This Row],[Novos Personais Ativados]] -> 241.64657 | O11: 0.02 | P11: =M10*Table15313[[#This Row],[Tx. % Churn]] -> 1.5719441 | Q11: =Table15313[[#This Row],[Personais Totais]]-Table15313[[#This Row],[Qtde. Churn no Mês]] -> 97.716636 | R11: 15 | S11: =S10*1.015 -> 274.72762 | T11: =Table15313[[#This Row],[Média Alunos Estimada Total Personal]]*Table15313[[#This Row],[Ticket Médio Aluno Personal]] -> 4120.9143 | U11: =Table15313[[#This Row],[Personais Ativos Mês]]+(Table15313[[#This Row],[Personais Ativos Mês]]*Table15313[[#This Row],[Média Alunos Estimada Total Personal]]) -> 1563.4662 | V11: =Table15313[[#This Row],[Média Faturamento Estimada Personal]]*Q10 -> 319102.79 | W11: =Table15313[[#This Row],[Faturamento Estimado]]*2% -> 6382.0558 | X11: =Table15313[[#This Row],[Média Alunos Estimada Total Personal]]-(Table15313[[#This Row],[Tx. % Real Alunos não ativados]]*Table15313[[#This Row],[Média Alunos Estimada Total Personal]]) -> 14.25 | Y11: 0.05 | Z11: =Table15313[[#This Row],[Ticket Médio Aluno Personal]]*Table15313[[#This Row],[Média Real Alunos Ativos Personal]] -> 3914.8686 | AA11: =Table15313[[#This Row],[Média Real Alunos Ativos Personal]]*Table15313[[#This Row],[Personais Ativos Mês]] -> 1392.4621 | AB11: =Table15313[[#This Row],[Média Real por Personal]]*Q10 -> 303147.65 | AC11: =Table15313[[#This Row],[Faturamento Real Bruto]]*2% -> 6062.953 | AD11: =AD10+Table15313[[#This Row],[Faturamento Real Bruto]] -> 1112821.5 | AE11: =AE10+Table15313[[#This Row],[Receita MUVX (2%)]] -> 22256.43 | AF11: =Table15313[[#This Row],[Investimento no Mês (Growth) // 5%]]+AF10 -> 18681.541 | AG11: =Table15313[[#This Row],[Receita MUVX Acumulada]]/Table15313[[#This Row],[Investimento Acumulado]] -> 1.1913594 | AH11: =Table15313[[#This Row],[ROI]]+AH10 -> 12.68004
A12: 46296 | B12: =B73*0.05 -> 5000 | C12: =C73 -> 12.918426 | D12: =Table15313[[#This Row],[Investimento no Mês (Growth) // 5%]]/Table15313[[#This Row],[CPL - Tráfego (cadastro)]] -> 387.04406 | E12: =E73 -> 0.3 | F12: =Table15313[[#This Row],[Novos Cadastros LP]]*Table15313[[#This Row],[Tx. % Install]] -> 116.11322 | G12: =G73 -> 0.6 | H12: =Table15313[[#This Row],[Novos Installs no App]]*Table15313[[#This Row],[Tx % Ativações]] -> 69.667932 | I12: =I73 -> 0.3 | J12: =J73*20% -> 0 | K12: =K73 -> 0 | L12: =(Table15313[[#This Row],[Novos Personais Habilitados]]*Table15313[[#This Row],[Tx % de Conversão]])+(Table15313[[#This Row],[Cadastros Evento Presencial]]*Table15313[[#This Row],[Tx % Ativação Presencial]]) -> 20.900379 | M12: =Table15313[[#This Row],[Novos Personais Ativados]]+M11 -> 120.18896 | N12: =Table15313[[#This Row],[Investimento no Mês (Growth) // 5%]]/Table15313[[#This Row],[Novos Personais Ativados]] -> 239.23011 | O12: 0.03 | P12: =M11*Table15313[[#This Row],[Tx. % Churn]] -> 2.9786574 | Q12: =Table15313[[#This Row],[Personais Totais]]-Table15313[[#This Row],[Qtde. Churn no Mês]] -> 117.2103 | R12: 15 | S12: =S11*1.015 -> 278.84853 | T12: =Table15313[[#This Row],[Média Alunos Estimada Total Personal]]*Table15313[[#This Row],[Ticket Médio Aluno Personal]] -> 4182.728 | U12: =Table15313[[#This Row],[Personais Ativos Mês]]+(Table15313[[#This Row],[Personais Ativos Mês]]*Table15313[[#This Row],[Média Alunos Estimada Total Personal]]) -> 1875.3648 | V12: =Table15313[[#This Row],[Média Faturamento Estimada Personal]]*Q11 -> 408722.11 | W12: =Table15313[[#This Row],[Faturamento Estimado]]*2% -> 8174.4422 | X12: =Table15313[[#This Row],[Média Alunos Estimada Total Personal]]-(Table15313[[#This Row],[Tx. % Real Alunos não ativados]]*Table15313[[#This Row],[Média Alunos Estimada Total Personal]]) -> 14.25 | Y12: 0.05 | Z12: =Table15313[[#This Row],[Ticket Médio Aluno Personal]]*Table15313[[#This Row],[Média Real Alunos Ativos Personal]] -> 3973.5916 | AA12: =Table15313[[#This Row],[Média Real Alunos Ativos Personal]]*Table15313[[#This Row],[Personais Ativos Mês]] -> 1670.2468 | AB12: =Table15313[[#This Row],[Média Real por Personal]]*Q11 -> 388286 | AC12: =Table15313[[#This Row],[Faturamento Real Bruto]]*2% -> 7765.7201 | AD12: =AD11+Table15313[[#This Row],[Faturamento Real Bruto]] -> 1501107.5 | AE12: =AE11+Table15313[[#This Row],[Receita MUVX (2%)]] -> 30022.15 | AF12: =Table15313[[#This Row],[Investimento no Mês (Growth) // 5%]]+AF11 -> 23681.541 | AG12: =Table15313[[#This Row],[Receita MUVX Acumulada]]/Table15313[[#This Row],[Investimento Acumulado]] -> 1.2677448 | AH12: =Table15313[[#This Row],[ROI]]+AH11 -> 13.947785
A13: 46327 | B13: =B74*0.05 -> 5000 | C13: =C74 -> 12.789241 | D13: =Table15313[[#This Row],[Investimento no Mês (Growth) // 5%]]/Table15313[[#This Row],[CPL - Tráfego (cadastro)]] -> 390.9536 | E13: =E74 -> 0.3 | F13: =Table15313[[#This Row],[Novos Cadastros LP]]*Table15313[[#This Row],[Tx. % Install]] -> 117.28608 | G13: =G74 -> 0.6 | H13: =Table15313[[#This Row],[Novos Installs no App]]*Table15313[[#This Row],[Tx % Ativações]] -> 70.371648 | I13: =I74 -> 0.3 | J13: =J74*20% -> 0 | K13: =K74 -> 0 | L13: =(Table15313[[#This Row],[Novos Personais Habilitados]]*Table15313[[#This Row],[Tx % de Conversão]])+(Table15313[[#This Row],[Cadastros Evento Presencial]]*Table15313[[#This Row],[Tx % Ativação Presencial]]) -> 21.111494 | M13: =Table15313[[#This Row],[Novos Personais Ativados]]+M12 -> 141.30045 | N13: =Table15313[[#This Row],[Investimento no Mês (Growth) // 5%]]/Table15313[[#This Row],[Novos Personais Ativados]] -> 236.8378 | O13: 0.02 | P13: =M12*Table15313[[#This Row],[Tx. % Churn]] -> 2.4037792 | Q13: =Table15313[[#This Row],[Personais Totais]]-Table15313[[#This Row],[Qtde. Churn no Mês]] -> 138.89667 | R13: 15 | S13: =S12*1.015 -> 283.03126 | T13: =Table15313[[#This Row],[Média Alunos Estimada Total Personal]]*Table15313[[#This Row],[Ticket Médio Aluno Personal]] -> 4245.4689 | U13: =Table15313[[#This Row],[Personais Ativos Mês]]+(Table15313[[#This Row],[Personais Ativos Mês]]*Table15313[[#This Row],[Média Alunos Estimada Total Personal]]) -> 2222.3468 | V13: =Table15313[[#This Row],[Média Faturamento Estimada Personal]]*Q12 -> 497612.7 | W13: =Table15313[[#This Row],[Faturamento Estimado]]*2% -> 9952.2539 | X13: =Table15313[[#This Row],[Média Alunos Estimada Total Personal]]-(Table15313[[#This Row],[Tx. % Real Alunos não ativados]]*Table15313[[#This Row],[Média Alunos Estimada Total Personal]]) -> 14.25 | Y13: 0.05 | Z13: =Table15313[[#This Row],[Ticket Médio Aluno Personal]]*Table15313[[#This Row],[Média Real Alunos Ativos Personal]] -> 4033.1955 | AA13: =Table15313[[#This Row],[Média Real Alunos Ativos Personal]]*Table15313[[#This Row],[Personais Ativos Mês]] -> 1979.2776 | AB13: =Table15313[[#This Row],[Média Real por Personal]]*Q12 -> 472732.06 | AC13: =Table15313[[#This Row],[Faturamento Real Bruto]]*2% -> 9454.6412 | AD13: =AD12+Table15313[[#This Row],[Faturamento Real Bruto]] -> 1973839.6 | AE13: =AE12+Table15313[[#This Row],[Receita MUVX (2%)]] -> 39476.791 | AF13: =Table15313[[#This Row],[Investimento no Mês (Growth) // 5%]]+AF12 -> 28681.541 | AG13: =Table15313[[#This Row],[Receita MUVX Acumulada]]/Table15313[[#This Row],[Investimento Acumulado]] -> 1.3763832 | AH13: =Table15313[[#This Row],[ROI]]+AH12 -> 15.324168
A14: 46357 | B14: =B75*0.05 -> 5000 | C14: =C75 -> 12.661349 | D14: =Table15313[[#This Row],[Investimento no Mês (Growth) // 5%]]/Table15313[[#This Row],[CPL - Tráfego (cadastro)]] -> 394.90263 | E14: =E75 -> 0.3 | F14: =Table15313[[#This Row],[Novos Cadastros LP]]*Table15313[[#This Row],[Tx. % Install]] -> 118.47079 | G14: =G75 -> 0.6 | H14: =Table15313[[#This Row],[Novos Installs no App]]*Table15313[[#This Row],[Tx % Ativações]] -> 71.082473 | I14: =I75 -> 0.3 | J14: =J75*20% -> 0 | K14: =K75 -> 0 | L14: =(Table15313[[#This Row],[Novos Personais Habilitados]]*Table15313[[#This Row],[Tx % de Conversão]])+(Table15313[[#This Row],[Cadastros Evento Presencial]]*Table15313[[#This Row],[Tx % Ativação Presencial]]) -> 21.324742 | M14: =Table15313[[#This Row],[Novos Personais Ativados]]+M13 -> 162.6252 | N14: =Table15313[[#This Row],[Investimento no Mês (Growth) // 5%]]/Table15313[[#This Row],[Novos Personais Ativados]] -> 234.46943 | O14: 0.03 | P14: =M13*Table15313[[#This Row],[Tx. % Churn]] -> 4.2390136 | Q14: =Table15313[[#This Row],[Personais Totais]]-Table15313[[#This Row],[Qtde. Churn no Mês]] -> 158.38618 | R14: 15 | S14: =S13*1.015 -> 287.27673 | T14: =Table15313[[#This Row],[Média Alunos Estimada Total Personal]]*Table15313[[#This Row],[Ticket Médio Aluno Personal]] -> 4309.151 | U14: =Table15313[[#This Row],[Personais Ativos Mês]]+(Table15313[[#This Row],[Personais Ativos Mês]]*Table15313[[#This Row],[Média Alunos Estimada Total Personal]]) -> 2534.1789 | V14: =Table15313[[#This Row],[Média Faturamento Estimada Personal]]*Q13 -> 598526.74 | W14: =Table15313[[#This Row],[Faturamento Estimado]]*2% -> 11970.535 | X14: =Table15313[[#This Row],[Média Alunos Estimada Total Personal]]-(Table15313[[#This Row],[Tx. % Real Alunos não ativados]]*Table15313[[#This Row],[Média Alunos Estimada Total Personal]]) -> 14.25 | Y14: 0.05 | Z14: =Table15313[[#This Row],[Ticket Médio Aluno Personal]]*Table15313[[#This Row],[Média Real Alunos Ativos Personal]] -> 4093.6934 | AA14: =Table15313[[#This Row],[Média Real Alunos Ativos Personal]]*Table15313[[#This Row],[Personais Ativos Mês]] -> 2257.0031 | AB14: =Table15313[[#This Row],[Média Real por Personal]]*Q13 -> 568600.4 | AC14: =Table15313[[#This Row],[Faturamento Real Bruto]]*2% -> 11372.008 | AD14: =AD13+Table15313[[#This Row],[Faturamento Real Bruto]] -> 2542440 | AE14: =AE13+Table15313[[#This Row],[Receita MUVX (2%)]] -> 50848.799 | AF14: =Table15313[[#This Row],[Investimento no Mês (Growth) // 5%]]+AF13 -> 33681.541 | AG14: =Table15313[[#This Row],[Receita MUVX Acumulada]]/Table15313[[#This Row],[Investimento Acumulado]] -> 1.5096934 | AH14: =Table15313[[#This Row],[ROI]]+AH13 -> 16.833861
A15: 46388 | B15: =B76*0.05 -> 5000 | C15: =C76 -> 12.534736 | D15: =Table15313[[#This Row],[Investimento no Mês (Growth) // 5%]]/Table15313[[#This Row],[CPL - Tráfego (cadastro)]] -> 398.89154 | E15: =E76 -> 0.3 | F15: =Table15313[[#This Row],[Novos Cadastros LP]]*Table15313[[#This Row],[Tx. % Install]] -> 119.66746 | G15: =G76 -> 0.6 | H15: =Table15313[[#This Row],[Novos Installs no App]]*Table15313[[#This Row],[Tx % Ativações]] -> 71.800478 | I15: =I76 -> 0.3 | J15: =J76*20% -> 0 | K15: =K76 -> 0 | L15: =(Table15313[[#This Row],[Novos Personais Habilitados]]*Table15313[[#This Row],[Tx % de Conversão]])+(Table15313[[#This Row],[Cadastros Evento Presencial]]*Table15313[[#This Row],[Tx % Ativação Presencial]]) -> 21.540143 | M15: =Table15313[[#This Row],[Novos Personais Ativados]]+M14 -> 184.16534 | N15: =Table15313[[#This Row],[Investimento no Mês (Growth) // 5%]]/Table15313[[#This Row],[Novos Personais Ativados]] -> 232.12473 | O15: 0.03 | P15: =M14*Table15313[[#This Row],[Tx. % Churn]] -> 4.8787559 | Q15: =Table15313[[#This Row],[Personais Totais]]-Table15313[[#This Row],[Qtde. Churn no Mês]] -> 179.28658 | R15: 15 | S15: =S14*1.015 -> 291.58588 | T15: =Table15313[[#This Row],[Média Alunos Estimada Total Personal]]*Table15313[[#This Row],[Ticket Médio Aluno Personal]] -> 4373.7882 | U15: =Table15313[[#This Row],[Personais Ativos Mês]]+(Table15313[[#This Row],[Personais Ativos Mês]]*Table15313[[#This Row],[Média Alunos Estimada Total Personal]]) -> 2868.5853 | V15: =Table15313[[#This Row],[Média Faturamento Estimada Personal]]*Q14 -> 692747.62 | W15: =Table15313[[#This Row],[Faturamento Estimado]]*2% -> 13854.952 | X15: =Table15313[[#This Row],[Média Alunos Estimada Total Personal]]-(Table15313[[#This Row],[Tx. % Real Alunos não ativados]]*Table15313[[#This Row],[Média Alunos Estimada Total Personal]]) -> 14.25 | Y15: 0.05 | Z15: =Table15313[[#This Row],[Ticket Médio Aluno Personal]]*Table15313[[#This Row],[Média Real Alunos Ativos Personal]] -> 4155.0988 | AA15: =Table15313[[#This Row],[Média Real Alunos Ativos Personal]]*Table15313[[#This Row],[Personais Ativos Mês]] -> 2554.8338 | AB15: =Table15313[[#This Row],[Média Real por Personal]]*Q14 -> 658110.24 | AC15: =Table15313[[#This Row],[Faturamento Real Bruto]]*2% -> 13162.205 | AD15: =AD14+Table15313[[#This Row],[Faturamento Real Bruto]] -> 3200550.2 | AE15: =AE14+Table15313[[#This Row],[Receita MUVX (2%)]] -> 64011.004 | AF15: =Table15313[[#This Row],[Investimento no Mês (Growth) // 5%]]+AF14 -> 38681.541 | AG15: =Table15313[[#This Row],[Receita MUVX Acumulada]]/Table15313[[#This Row],[Investimento Acumulado]] -> 1.6548204 | AH15: =Table15313[[#This Row],[ROI]]+AH14 -> 18.488682
A16: 46419 | B16: =B77*0.05 -> 5000 | C16: =C77 -> 12.409388 | D16: =Table15313[[#This Row],[Investimento no Mês (Growth) // 5%]]/Table15313[[#This Row],[CPL - Tráfego (cadastro)]] -> 402.92075 | E16: =E77 -> 0.3 | F16: =Table15313[[#This Row],[Novos Cadastros LP]]*Table15313[[#This Row],[Tx. % Install]] -> 120.87622 | G16: =G77 -> 0.6 | H16: =Table15313[[#This Row],[Novos Installs no App]]*Table15313[[#This Row],[Tx % Ativações]] -> 72.525735 | I16: =I77 -> 0.3 | J16: =J77*20% -> 0 | K16: =K77 -> 0 | L16: =(Table15313[[#This Row],[Novos Personais Habilitados]]*Table15313[[#This Row],[Tx % de Conversão]])+(Table15313[[#This Row],[Cadastros Evento Presencial]]*Table15313[[#This Row],[Tx % Ativação Presencial]]) -> 21.75772 | M16: =Table15313[[#This Row],[Novos Personais Ativados]]+M15 -> 205.92306 | N16: =Table15313[[#This Row],[Investimento no Mês (Growth) // 5%]]/Table15313[[#This Row],[Novos Personais Ativados]] -> 229.80349 | O16: 0.06 | P16: =M15*Table15313[[#This Row],[Tx. % Churn]] -> 11.04992 | Q16: =Table15313[[#This Row],[Personais Totais]]-Table15313[[#This Row],[Qtde. Churn no Mês]] -> 194.87314 | R16: 15 | S16: =S15*1.015 -> 295.95967 | T16: =Table15313[[#This Row],[Média Alunos Estimada Total Personal]]*Table15313[[#This Row],[Ticket Médio Aluno Personal]] -> 4439.3951 | U16: =Table15313[[#This Row],[Personais Ativos Mês]]+(Table15313[[#This Row],[Personais Ativos Mês]]*Table15313[[#This Row],[Média Alunos Estimada Total Personal]]) -> 3117.9702 | V16: =Table15313[[#This Row],[Média Faturamento Estimada Personal]]*Q15 -> 795923.97 | W16: =Table15313[[#This Row],[Faturamento Estimado]]*2% -> 15918.479 | X16: =Table15313[[#This Row],[Média Alunos Estimada Total Personal]]-(Table15313[[#This Row],[Tx. % Real Alunos não ativados]]*Table15313[[#This Row],[Média Alunos Estimada Total Personal]]) -> 14.25 | Y16: 0.05 | Z16: =Table15313[[#This Row],[Ticket Médio Aluno Personal]]*Table15313[[#This Row],[Média Real Alunos Ativos Personal]] -> 4217.4253 | AA16: =Table15313[[#This Row],[Média Real Alunos Ativos Personal]]*Table15313[[#This Row],[Personais Ativos Mês]] -> 2776.9422 | AB16: =Table15313[[#This Row],[Média Real por Personal]]*Q15 -> 756127.77 | AC16: =Table15313[[#This Row],[Faturamento Real Bruto]]*2% -> 15122.555 | AD16: =AD15+Table15313[[#This Row],[Faturamento Real Bruto]] -> 3956678 | AE16: =AE15+Table15313[[#This Row],[Receita MUVX (2%)]] -> 79133.56 | AF16: =Table15313[[#This Row],[Investimento no Mês (Growth) // 5%]]+AF15 -> 43681.541 | AG16: =Table15313[[#This Row],[Receita MUVX Acumulada]]/Table15313[[#This Row],[Investimento Acumulado]] -> 1.8116018 | AH16: =Table15313[[#This Row],[ROI]]+AH15 -> 20.300284
B17: =SUBTOTAL(109,B3:B16) -> 43681.541 | C17: =SUBTOTAL(101,C3:C16) -> 13.105041 | D17: =SUBTOTAL(109,D3:D16) -> 4411.5457 | E17: =AVERAGE(E3:E16) -> 0.25428571 | F17: =Table15313[[#This Row],[Novos Cadastros LP]]*Table15313[[#This Row],[Tx. % Install]] -> 1121.7931 | G17: =G78 -> 0.53571429 | H17: =Table15313[[#This Row],[Novos Installs no App]]*Table15313[[#This Row],[Tx % Ativações]] -> 600.96057 | I17: =I78 -> 0.32857143 | L17: =SUBTOTAL(109,L3:L16) -> 205.92306 | M17: =AVERAGE(M3:M16) -> 86.640036 | N17: =SUBTOTAL(101,N3:N16) -> #DIV/0! | O17: =AVERAGE(O3:O16) -> 0.025714286 | P17: =SUBTOTAL(109,P3:P16) -> 32.485006 | Q17: =Q16 -> 194.87314 | R17: =AVERAGE(R3:R16) -> 15 | S17: =Table15313[[#This Row],[Média Faturamento Estimada Personal]]/Table15313[[#This Row],[Média Alunos Estimada Total Personal]] -> 251.90031 | T17: =SUBTOTAL(101,T3:T16) -> 3778.5047 | U17: =Table15313[[#This Row],[Personais Ativos Mês]]+(Table15313[[#This Row],[Personais Ativos Mês]]*Table15313[[#This Row],[Média Alunos Estimada Total Personal]]) -> 3117.9702 | V17: =SUBTOTAL(109,V3:V16) -> 4164924.2 | W17: =Table15313[[#This Row],[Faturamento Estimado]]*2% -> 83298.484 | Z17: =AVERAGE(Z4:Z16) -> 3678.2009 | AB17: =SUBTOTAL(109,AB3:AB16) -> 3956678 | AC17: =SUBTOTAL(109,AC3:AC16) -> 79133.56
G18: =G79 -> 0 | I18: =I79 -> 0
C19: % sob TAM Nacional | D19: =D17/130000 -> 0.033934967 | F19: =Table15313[[#This Row],[Novos Cadastros LP]]*Table15313[[#This Row],[Tx. % Install]] -> 0 | G19: =G80 -> 0 | H19: =Table15313[[#This Row],[Novos Installs no App]]*Table15313[[#This Row],[Tx % Ativações]] -> 0 | I19: =I80 -> 0 | P19: % sob TAM Nacional | Q19: =Q17/130000 -> 0.0014990241
C21: Top | E21: Install | G21: Ativação | I21: Conversão | N21: Cenário sem perdas operacionais | X21: Cenário com perdas operacionais
